2025-08-14 16:49:11,978 - agent - INFO - 使用配置文件的日志
2025-08-14 16:49:27,876 - agent - INFO - 使用配置文件的日志
2025-08-14 16:50:22,972 - agent - INFO - 使用配置文件的日志
2025-08-14 19:39:52,865 - agent - INFO - 使用配置文件的日志
2025-08-14 19:49:42,672 - asyncio - ERROR - Exception in callback EventConsumer.agent_task_callback() at C:\01_Work\04_Soft\01_Programs\miniconda3\envs\a2a_env\Lib\site-packages\a2a\server\events\event_consumer.py:153
handle: <Handle EventConsumer.agent_task_callback() at C:\01_Work\04_Soft\01_Programs\miniconda3\envs\a2a_env\Lib\site-packages\a2a\server\events\event_consumer.py:153>
Traceback (most recent call last):
  File "C:\01_Work\04_Soft\01_Programs\miniconda3\envs\a2a_env\Lib\site-packages\langgraph\pregel\main.py", line 2881, in astream
    async with AsyncPregelLoop(
               ~~~~~~~~~~~~~~~^
        input,
        ^^^^^^
    ...<17 lines>...
        cache_policy=self.cache_policy,
        ^^^^^^^^^^^^^^^^^^^^^^^^^^^^^^^
    ) as loop:
    ^
  File "C:\01_Work\04_Soft\01_Programs\miniconda3\envs\a2a_env\Lib\site-packages\langgraph\pregel\_loop.py", line 1230, in __aexit__
    return await exit_task
           ^^^^^^^^^^^^^^^
  File "C:\01_Work\04_Soft\01_Programs\miniconda3\envs\a2a_env\Lib\contextlib.py", line 768, in __aexit__
    raise exc
  File "C:\01_Work\04_Soft\01_Programs\miniconda3\envs\a2a_env\Lib\contextlib.py", line 751, in __aexit__
    cb_suppress = await cb(*exc_details)
                  ^^^^^^^^^^^^^^^^^^^^^^
  File "C:\01_Work\04_Soft\01_Programs\miniconda3\envs\a2a_env\Lib\site-packages\langgraph\pregel\_executor.py", line 201, in __aexit__
    await asyncio.wait(tasks)
  File "C:\01_Work\04_Soft\01_Programs\miniconda3\envs\a2a_env\Lib\asyncio\tasks.py", line 451, in wait
    return await _wait(fs, timeout, return_when, loop)
           ^^^^^^^^^^^^^^^^^^^^^^^^^^^^^^^^^^^^^^^^^^^
  File "C:\01_Work\04_Soft\01_Programs\miniconda3\envs\a2a_env\Lib\asyncio\tasks.py", line 537, in _wait
    await waiter
asyncio.exceptions.CancelledError: ('Cancelled by cancel scope 260d47de270', <Task cancelled name='Task-35' coro=<AsyncExitStack.__aexit__() done, defined at C:\01_Work\04_Soft\01_Programs\miniconda3\envs\a2a_env\Lib\contextlib.py:716>>)

During handling of the above exception, another exception occurred:

Traceback (most recent call last):
  File "C:\01_Work\04_Soft\01_Programs\miniconda3\envs\a2a_env\Lib\asyncio\events.py", line 89, in _run
    self._context.run(self._callback, *self._args)
    ~~~~~~~~~~~~~~~~~^^^^^^^^^^^^^^^^^^^^^^^^^^^^^
  File "C:\01_Work\04_Soft\01_Programs\miniconda3\envs\a2a_env\Lib\site-packages\a2a\utils\telemetry.py", line 234, in sync_wrapper
    result = func(*args, **kwargs)
  File "C:\01_Work\04_Soft\01_Programs\miniconda3\envs\a2a_env\Lib\site-packages\a2a\server\events\event_consumer.py", line 163, in agent_task_callback
    if agent_task.exception() is not None:
       ~~~~~~~~~~~~~~~~~~~~^^
  File "C:\01_Work\04_Soft\01_Programs\miniconda3\envs\a2a_env\Lib\site-packages\a2a\utils\telemetry.py", line 194, in async_wrapper
    result = await func(*args, **kwargs)
             ^^^^^^^^^^^^^^^^^^^^^^^^^^^
  File "C:\01_Work\04_Soft\01_Programs\miniconda3\envs\a2a_env\Lib\site-packages\a2a\server\request_handlers\default_request_handler.py", line 172, in _run_event_stream
    await self.agent_executor.execute(request, queue)
  File "C:\01_Work\01_Project\AI\A2A_Sample_V030\remote_server\chat_agent\src\agent_executor.py", line 32, in execute
    async for chunk in self.agent.stream(messages=user_input, session_id=session_id):
    ...<19 lines>...
            break
  File "C:\01_Work\01_Project\AI\A2A_Sample_V030\remote_server\chat_agent\src\agent.py", line 41, in stream
    async for item in self.graph.astream(input={"messages": messages},config=config, stream_mode='messages'):
    ...<4 lines>...
                }
  File "C:\01_Work\04_Soft\01_Programs\miniconda3\envs\a2a_env\Lib\site-packages\langgraph\pregel\main.py", line 2979, in astream
    await asyncio.shield(run_manager.on_chain_error(e))
asyncio.exceptions.CancelledError: Cancelled by cancel scope 260d47de270
2025-08-14 19:53:56,838 - agent - INFO - 使用配置文件的日志
2025-08-14 19:54:26,136 - asyncio - ERROR - Exception in callback EventConsumer.agent_task_callback() at C:\01_Work\04_Soft\01_Programs\miniconda3\envs\a2a_env\Lib\site-packages\a2a\server\events\event_consumer.py:153
handle: <Handle EventConsumer.agent_task_callback() at C:\01_Work\04_Soft\01_Programs\miniconda3\envs\a2a_env\Lib\site-packages\a2a\server\events\event_consumer.py:153>
Traceback (most recent call last):
  File "C:\01_Work\04_Soft\01_Programs\miniconda3\envs\a2a_env\Lib\site-packages\langgraph\pregel\main.py", line 2881, in astream
    async with AsyncPregelLoop(
               ~~~~~~~~~~~~~~~^
        input,
        ^^^^^^
    ...<17 lines>...
        cache_policy=self.cache_policy,
        ^^^^^^^^^^^^^^^^^^^^^^^^^^^^^^^
    ) as loop:
    ^
  File "C:\01_Work\04_Soft\01_Programs\miniconda3\envs\a2a_env\Lib\site-packages\langgraph\pregel\_loop.py", line 1230, in __aexit__
    return await exit_task
           ^^^^^^^^^^^^^^^
  File "C:\01_Work\04_Soft\01_Programs\miniconda3\envs\a2a_env\Lib\contextlib.py", line 768, in __aexit__
    raise exc
  File "C:\01_Work\04_Soft\01_Programs\miniconda3\envs\a2a_env\Lib\contextlib.py", line 751, in __aexit__
    cb_suppress = await cb(*exc_details)
                  ^^^^^^^^^^^^^^^^^^^^^^
  File "C:\01_Work\04_Soft\01_Programs\miniconda3\envs\a2a_env\Lib\site-packages\langgraph\pregel\_executor.py", line 201, in __aexit__
    await asyncio.wait(tasks)
  File "C:\01_Work\04_Soft\01_Programs\miniconda3\envs\a2a_env\Lib\asyncio\tasks.py", line 451, in wait
    return await _wait(fs, timeout, return_when, loop)
           ^^^^^^^^^^^^^^^^^^^^^^^^^^^^^^^^^^^^^^^^^^^
  File "C:\01_Work\04_Soft\01_Programs\miniconda3\envs\a2a_env\Lib\asyncio\tasks.py", line 537, in _wait
    await waiter
asyncio.exceptions.CancelledError: ('Cancelled by cancel scope 1c8c00ae270', <Task cancelled name='Task-58' coro=<AsyncExitStack.__aexit__() done, defined at C:\01_Work\04_Soft\01_Programs\miniconda3\envs\a2a_env\Lib\contextlib.py:716>>)

During handling of the above exception, another exception occurred:

Traceback (most recent call last):
  File "C:\01_Work\04_Soft\01_Programs\miniconda3\envs\a2a_env\Lib\asyncio\events.py", line 89, in _run
    self._context.run(self._callback, *self._args)
    ~~~~~~~~~~~~~~~~~^^^^^^^^^^^^^^^^^^^^^^^^^^^^^
  File "C:\01_Work\04_Soft\01_Programs\miniconda3\envs\a2a_env\Lib\site-packages\a2a\utils\telemetry.py", line 234, in sync_wrapper
    result = func(*args, **kwargs)
  File "C:\01_Work\04_Soft\01_Programs\miniconda3\envs\a2a_env\Lib\site-packages\a2a\server\events\event_consumer.py", line 163, in agent_task_callback
    if agent_task.exception() is not None:
       ~~~~~~~~~~~~~~~~~~~~^^
  File "C:\01_Work\04_Soft\01_Programs\miniconda3\envs\a2a_env\Lib\site-packages\a2a\utils\telemetry.py", line 194, in async_wrapper
    result = await func(*args, **kwargs)
             ^^^^^^^^^^^^^^^^^^^^^^^^^^^
  File "C:\01_Work\04_Soft\01_Programs\miniconda3\envs\a2a_env\Lib\site-packages\a2a\server\request_handlers\default_request_handler.py", line 172, in _run_event_stream
    await self.agent_executor.execute(request, queue)
  File "C:\01_Work\01_Project\AI\A2A_Sample_V030\remote_server\chat_agent\src\agent_executor.py", line 32, in execute
    async for chunk in self.agent.stream(messages=user_input, session_id=session_id):
    ...<19 lines>...
            break
  File "C:\01_Work\01_Project\AI\A2A_Sample_V030\remote_server\chat_agent\src\agent.py", line 41, in stream
    async for item in self.graph.astream(input={"messages": messages},config=config, stream_mode='messages'):
    ...<4 lines>...
                }
  File "C:\01_Work\04_Soft\01_Programs\miniconda3\envs\a2a_env\Lib\site-packages\langgraph\pregel\main.py", line 2979, in astream
    await asyncio.shield(run_manager.on_chain_error(e))
asyncio.exceptions.CancelledError: Cancelled by cancel scope 1c8c00ae270
2025-08-14 19:55:39,104 - agent - INFO - 使用配置文件的日志
2025-08-15 08:15:31,047 - agent - INFO - 使用配置文件的日志
2025-08-16 14:42:35,943 - agent - INFO - 使用配置文件的日志
